<?xml version="1.0" ?>
<!-- =================================================================================== -->
<!-- |    This document was autogenerated by xacro from /home/loc/new_design_ws/src/thietkemoi/thanxe_new_description/urdf/complete_visual.xacro | -->
<!-- |    EDITING THIS FILE BY HAND IS NOT RECOMMENDED                                 | -->
<!-- =================================================================================== -->
<robot name="complete_visual">
  <material name="silver">
    <color rgba="0.700 0.700 0.700 1.000"/>
  </material>
  <material name="white">
    <color rgba="1.0 1.0 1.0 1.0"/>
  </material>
  <material name="black">
    <color rgba="0.0 0.0 0.0 1.0"/>
  </material>
  <material name="dark_grey">
    <color rgba="0.2 0.2 0.2 1.0"/>
  </material>
  <material name="steel">
    <color rgba="0.5 0.5 0.5 1.0"/>
  </material>
  <material name="gold">
    <color rgba="1.0 0.84 0.0 1.0"/>
  </material>
  <material name="orange">
    <color rgba="1.0 0.42 0.04 1.0"/>
  </material>
  <material name="blue">
    <color rgba="0.0 0.0 0.8 1.0"/>
  </material>
  <material name="midnight_blue">
    <color rgba="0.1 0.1 0.4 1.0"/>
  </material>
  <material name="red">
    <color rgba="0.8 0.0 0.0 1.0"/>
  </material>
  <gazebo reference="base_link">
    <material>Gazebo/Silver</material>
    <mu1>0.2</mu1>
    <mu2>0.2</mu2>
    <self_collide>false</self_collide>
    <gravity>true</gravity>
    <linearDamping>5.0</linearDamping>
    <angularDamping>5.0</angularDamping>
  </gazebo>
  <gazebo reference="Revolute1_1">
    <material>Gazebo/Silver</material>
    <mu1>0.2</mu1>
    <mu2>0.2</mu2>
    <self_collide>false</self_collide>
  </gazebo>
  <gazebo reference="Revolute2_1">
    <material>Gazebo/Silver</material>
    <mu1>0.2</mu1>
    <mu2>0.2</mu2>
    <self_collide>false</self_collide>
  </gazebo>
  <gazebo reference="Revolute3_1">
    <material>Gazebo/Silver</material>
    <mu1>0.2</mu1>
    <mu2>0.2</mu2>
    <self_collide>false</self_collide>
  </gazebo>
  <gazebo reference="Revolute4_1">
    <material>Gazebo/Silver</material>
    <mu1>0.2</mu1>
    <mu2>0.2</mu2>
    <self_collide>false</self_collide>
  </gazebo>
  <gazebo reference="Wheel1_1">
    <material>Gazebo/Silver</material>
    <mu1>1.0</mu1>
    <mu2>0.2</mu2>
    <kp>1000000</kp>
    <kd>20</kd>
    <minDepth>0.001</minDepth>
    <maxVel>0.5</maxVel>
    <fdir1>1 0 0</fdir1>
  </gazebo>
  <gazebo reference="Wheel2_1">
    <material>Gazebo/Silver</material>
    <mu1>1.0</mu1>
    <mu2>0.2</mu2>
    <kp>1000000</kp>
    <kd>20</kd>
    <minDepth>0.001</minDepth>
    <maxVel>0.5</maxVel>
    <fdir1>1 0 0</fdir1>
  </gazebo>
  <gazebo reference="Wheel3_1">
    <material>Gazebo/Silver</material>
    <mu1>1.0</mu1>
    <mu2>0.2</mu2>
    <kp>1000000</kp>
    <kd>20</kd>
    <minDepth>0.001</minDepth>
    <maxVel>0.5</maxVel>
    <fdir1>1 0 0</fdir1>
  </gazebo>
  <gazebo reference="Wheel4_1">
    <material>Gazebo/Silver</material>
    <mu1>1.0</mu1>
    <mu2>0.2</mu2>
    <kp>10000000.0</kp>
    <kd>20.0</kd>
    <minDepth>0.001</minDepth>
    <maxVel>0.5</maxVel>
    <fdir1>1 0 0</fdir1>
  </gazebo>
  <gazebo reference="base_link">
    <material>Gazebo/White</material>
  </gazebo>
  <gazebo reference="Revolute1_1">
    <material>Gazebo/Gold</material>
  </gazebo>
  <gazebo reference="Revolute2_1">
    <material>Gazebo/Gold</material>
  </gazebo>
  <gazebo reference="Revolute3_1">
    <material>Gazebo/Gold</material>
  </gazebo>
  <gazebo reference="Revolute4_1">
    <material>Gazebo/Gold</material>
  </gazebo>
  <gazebo reference="Wheel1_1">
    <material>Gazebo/Black</material>
  </gazebo>
  <gazebo reference="Wheel2_1">
    <material>Gazebo/Black</material>
  </gazebo>
  <gazebo reference="Wheel3_1">
    <material>Gazebo/Black</material>
  </gazebo>
  <gazebo reference="Wheel4_1">
    <material>Gazebo/Black</material>
  </gazebo>
  <gazebo reference="Charge_link">
    <material>Gazebo/Gold</material>
  </gazebo>
  <gazebo reference="camera_link">
    <material>Gazebo/Red</material>
  </gazebo>
  <gazebo reference="shoulder_link">
    <material>Gazebo/Grey</material>
  </gazebo>
  <gazebo reference="upper_arm_link">
    <material>Gazebo/Grey</material>
  </gazebo>
  <gazebo reference="forearm_link">
    <material>Gazebo/Grey</material>
  </gazebo>
  <gazebo reference="wrist_1_link">
    <material>Gazebo/Blue</material>
  </gazebo>
  <gazebo reference="wrist_2_link">
    <material>Gazebo/Grey</material>
  </gazebo>
  <gazebo reference="wrist_3_link">
    <material>Gazebo/Grey</material>
  </gazebo>
  <gazebo reference="tool0">
    <material>Gazebo/Red</material>
  </gazebo>
  <!-- Specify some standard inertial calculations https://en.wikipedia.org/wiki/List_of_moments_of_inertia -->
  <!-- These make use of xacro's mathematical functionality -->
  <ros2_control name="GazeboSystem" type="system">
    <hardware>
      <plugin>gazebo_ros2_control/GazeboSystem</plugin>
    </hardware>
    <joint name="Revolute1_to_base_link">
      <command_interface name="position">
        <param name="min">-3.14</param>
        <param name="max">3.14</param>
      </command_interface>
      <state_interface name="velocity"/>
      <state_interface name="position"/>
    </joint>
    <joint name="Revolute2_to_base_link">
      <command_interface name="position">
        <param name="min">-3.14</param>
        <param name="max">3.14</param>
      </command_interface>
      <state_interface name="velocity"/>
      <state_interface name="position"/>
    </joint>
    <joint name="Revolute3_to_base_link">
      <command_interface name="position">
        <param name="min">-3.14</param>
        <param name="max">3.14</param>
      </command_interface>
      <state_interface name="velocity"/>
      <state_interface name="position"/>
    </joint>
    <joint name="Revolute4_to_base_link">
      <command_interface name="position">
        <param name="min">-3.14</param>
        <param name="max">3.14</param>
      </command_interface>
      <state_interface name="velocity"/>
      <state_interface name="position"/>
    </joint>
    <joint name="Wheel1_to_Revolute1">
      <command_interface name="velocity">
        <param name="min">-10</param>
        <param name="max">10</param>
      </command_interface>
      <state_interface name="velocity"/>
      <state_interface name="position"/>
    </joint>
    <joint name="Wheel2_to_Revolute2">
      <command_interface name="velocity">
        <param name="min">-10</param>
        <param name="max">10</param>
      </command_interface>
      <state_interface name="velocity"/>
      <state_interface name="position"/>
    </joint>
    <joint name="Wheel3_to_Revolute3">
      <command_interface name="velocity">
        <param name="min">-10</param>
        <param name="max">10</param>
      </command_interface>
      <state_interface name="velocity"/>
      <state_interface name="position"/>
    </joint>
    <joint name="Wheel4_to_Revolute4">
      <command_interface name="velocity">
        <param name="min">-10</param>
        <param name="max">10</param>
      </command_interface>
      <state_interface name="velocity"/>
      <state_interface name="position"/>
    </joint>
  </ros2_control>
  <!-- Nếu muốn điều khiển riêng thân xe thì bỏ comment các dòng bên dứoi và ngược lại điều khiển kết hợp thì comment điều khiển thân xe-->
  <!-- <gazebo>
        <plugin name="gazebo_ros2_control" filename="libgazebo_ros2_control.so">
            <parameters>$(find thanxe_new_description)/config/my_controllers.yaml</parameters>
        </plugin>
    </gazebo> -->
  <!-- <gazebo>
        <plugin name="gazebo_ros2_control" filename="libgazebo_ros2_control.so">
            <parameters>$(find thanxe_new_description)/config/combine_controller.yaml</parameters>
        </plugin>
    </gazebo> -->
  <link name="base_footprint">
</link>
  <joint name="base_footprint_joint" type="fixed">
    <parent link="base_footprint"/>
    <child link="base_link"/>
    <origin rpy="0 0 0" xyz="0 0 0"/>
  </joint>
  <link name="base_link">
    <inertial>
      <origin rpy="0 0 0" xyz="0 0 0.35"/>
      <mass value="150"/>
      <inertia ixx="21.53125" ixy="0.0" ixz="0.0" iyy="53.0" iyz="0.0" izz="49.53125000000001"/>
    </inertial>
    <visual>
      <origin rpy="0 0 0" xyz="0 0 0"/>
      <geometry>
        <mesh filename="file:///home/loc/new_design_ws/install/thanxe_new_description/share/thanxe_new_description/meshes/base_link.stl" scale="0.001 0.001 0.001"/>
      </geometry>
      <material name="white"/>
    </visual>
    <collision>
      <origin rpy="0 0 0" xyz="0 0 0"/>
      <geometry>
        <!-- <mesh filename="file://$(find thanxe_new_description)/meshes/base_link.stl" scale="0.001 0.001 0.001"/> -->
        <box size="0.018 0.015 0.010"/>
      </geometry>
    </collision>
  </link>
  <link name="Revolute1_1">
    <inertial>
      <origin rpy="0 0 0" xyz="0 0 -0.17"/>
      <mass value="3.0"/>
      <inertia ixx="0.028581250000000002" ixy="0.0" ixz="0.0" iyy="0.028581250000000002" iyz="0.0" izz="0.0091125"/>
    </inertial>
    <visual>
      <origin rpy="0 0 0" xyz="-0.738 -0.255 -0.355"/>
      <geometry>
        <mesh filename="file:///home/loc/new_design_ws/install/thanxe_new_description/share/thanxe_new_description/meshes/Revolute1_1.stl" scale="0.001 0.001 0.001"/>
      </geometry>
      <material name="gold"/>
    </visual>
    <collision>
      <origin rpy="0 0 0" xyz="-0.738 -0.255 -0.355"/>
      <geometry>
        <mesh filename="file:///home/loc/new_design_ws/install/thanxe_new_description/share/thanxe_new_description/meshes/Revolute1_1.stl" scale="0.001 0.001 0.001"/>
      </geometry>
    </collision>
  </link>
  <link name="Revolute2_1">
    <inertial>
      <origin rpy="0 0 0" xyz="0 0 -0.17"/>
      <mass value="3.0"/>
      <inertia ixx="0.028581250000000002" ixy="0.0" ixz="0.0" iyy="0.028581250000000002" iyz="0.0" izz="0.0091125"/>
    </inertial>
    <visual>
      <origin rpy="0 0 0" xyz="-0.738 0.255 -0.355"/>
      <geometry>
        <mesh filename="file:///home/loc/new_design_ws/install/thanxe_new_description/share/thanxe_new_description/meshes/Revolute2_1.stl" scale="0.001 0.001 0.001"/>
      </geometry>
      <material name="gold"/>
    </visual>
    <collision>
      <origin rpy="0 0 0" xyz="-0.738 0.255 -0.355"/>
      <geometry>
        <mesh filename="file:///home/loc/new_design_ws/install/thanxe_new_description/share/thanxe_new_description/meshes/Revolute2_1.stl" scale="0.001 0.001 0.001"/>
      </geometry>
    </collision>
  </link>
  <link name="Revolute3_1">
    <inertial>
      <origin rpy="0 0 0" xyz="0 0 -0.17"/>
      <mass value="3.0"/>
      <inertia ixx="0.028581250000000002" ixy="0.0" ixz="0.0" iyy="0.028581250000000002" iyz="0.0" izz="0.0091125"/>
    </inertial>
    <visual>
      <origin rpy="0 0 0" xyz="0.738 -0.255 -0.355"/>
      <geometry>
        <mesh filename="file:///home/loc/new_design_ws/install/thanxe_new_description/share/thanxe_new_description/meshes/Revolute3_1.stl" scale="0.001 0.001 0.001"/>
      </geometry>
      <material name="gold"/>
    </visual>
    <collision>
      <origin rpy="0 0 0" xyz="0.738 -0.255 -0.355"/>
      <geometry>
        <mesh filename="file:///home/loc/new_design_ws/install/thanxe_new_description/share/thanxe_new_description/meshes/Revolute3_1.stl" scale="0.001 0.001 0.001"/>
      </geometry>
    </collision>
  </link>
  <link name="Revolute4_1">
    <inertial>
      <origin rpy="0 0 0" xyz="0 0 -0.17"/>
      <mass value="3.0"/>
      <inertia ixx="0.028581250000000002" ixy="0.0" ixz="0.0" iyy="0.028581250000000002" iyz="0.0" izz="0.0091125"/>
    </inertial>
    <visual>
      <origin rpy="0 0 0" xyz="0.738 0.255 -0.355"/>
      <geometry>
        <mesh filename="file:///home/loc/new_design_ws/install/thanxe_new_description/share/thanxe_new_description/meshes/Revolute4_1.stl" scale="0.001 0.001 0.001"/>
      </geometry>
      <material name="gold"/>
    </visual>
    <collision>
      <origin rpy="0 0 0" xyz="0.738 0.255 -0.355"/>
      <geometry>
        <mesh filename="file:///home/loc/new_design_ws/install/thanxe_new_description/share/thanxe_new_description/meshes/Revolute4_1.stl" scale="0.001 0.001 0.001"/>
      </geometry>
    </collision>
  </link>
  <link name="Wheel1_1">
    <inertial>
      <origin rpy="1.57 0 0" xyz="0 0 0"/>
      <mass value="15.0"/>
      <inertia ixx="0.06171875" ixy="0.0" ixz="0.0" iyy="0.06171875" iyz="0.0" izz="0.1171875"/>
    </inertial>
    <visual>
      <origin rpy="0 0 0" xyz="-0.738 -0.255 -0.125"/>
      <geometry>
        <mesh filename="file:///home/loc/new_design_ws/install/thanxe_new_description/share/thanxe_new_description/meshes/Wheel1_1.stl" scale="0.001 0.001 0.001"/>
      </geometry>
      <material name="black"/>
    </visual>
    <collision>
      <origin rpy="0 0 0" xyz="-0.738 -0.255 -0.125"/>
      <geometry>
        <mesh filename="file:///home/loc/new_design_ws/install/thanxe_new_description/share/thanxe_new_description/meshes/Wheel1_1.stl" scale="0.001 0.001 0.001"/>
      </geometry>
    </collision>
  </link>
  <link name="Wheel2_1">
    <inertial>
      <origin rpy="1.57 0 0" xyz="0 0 0"/>
      <mass value="15.0"/>
      <inertia ixx="0.06171875" ixy="0.0" ixz="0.0" iyy="0.06171875" iyz="0.0" izz="0.1171875"/>
    </inertial>
    <visual>
      <origin rpy="0 0 0" xyz="-0.738 0.255 -0.125"/>
      <geometry>
        <mesh filename="file:///home/loc/new_design_ws/install/thanxe_new_description/share/thanxe_new_description/meshes/Wheel2_1.stl" scale="0.001 0.001 0.001"/>
      </geometry>
      <material name="black"/>
    </visual>
    <collision>
      <origin rpy="0 0 0" xyz="-0.738 0.255 -0.125"/>
      <geometry>
        <mesh filename="file:///home/loc/new_design_ws/install/thanxe_new_description/share/thanxe_new_description/meshes/Wheel2_1.stl" scale="0.001 0.001 0.001"/>
      </geometry>
    </collision>
  </link>
  <link name="Wheel3_1">
    <inertial>
      <origin rpy="1.57 0 0" xyz="0 0 0"/>
      <mass value="15.0"/>
      <inertia ixx="0.06171875" ixy="0.0" ixz="0.0" iyy="0.06171875" iyz="0.0" izz="0.1171875"/>
    </inertial>
    <visual>
      <origin rpy="0 0 0" xyz="0.738 -0.255 -0.125"/>
      <geometry>
        <mesh filename="file:///home/loc/new_design_ws/install/thanxe_new_description/share/thanxe_new_description/meshes/Wheel3_1.stl" scale="0.001 0.001 0.001"/>
      </geometry>
      <material name="black"/>
    </visual>
    <collision>
      <origin rpy="0 0 0" xyz="0.738 -0.255 -0.125"/>
      <geometry>
        <mesh filename="file:///home/loc/new_design_ws/install/thanxe_new_description/share/thanxe_new_description/meshes/Wheel3_1.stl" scale="0.001 0.001 0.001"/>
      </geometry>
    </collision>
  </link>
  <link name="Wheel4_1">
    <inertial>
      <origin rpy="1.57 0 0" xyz="0 0 0"/>
      <mass value="15.0"/>
      <inertia ixx="0.06171875" ixy="0.0" ixz="0.0" iyy="0.06171875" iyz="0.0" izz="0.1171875"/>
    </inertial>
    <visual>
      <origin rpy="0 0 0" xyz="0.738 0.255 -0.125"/>
      <geometry>
        <mesh filename="file:///home/loc/new_design_ws/install/thanxe_new_description/share/thanxe_new_description/meshes/Wheel4_1.stl" scale="0.001 0.001 0.001"/>
      </geometry>
      <material name="black"/>
    </visual>
    <collision>
      <origin rpy="0 0 0" xyz="0.738 0.255 -0.125"/>
      <geometry>
        <mesh filename="file:///home/loc/new_design_ws/install/thanxe_new_description/share/thanxe_new_description/meshes/Wheel4_1.stl" scale="0.001 0.001 0.001"/>
      </geometry>
    </collision>
  </link>
  <joint name="Revolute1_to_base_link" type="continuous">
    <origin rpy="0 0 0" xyz="0.738 0.255 0.355"/>
    <parent link="base_link"/>
    <child link="Revolute1_1"/>
    <axis xyz="0.0 -0.0 1.0"/>
    <limit effort="10000" velocity="30.0"/>
  </joint>
  <joint name="Revolute2_to_base_link" type="continuous">
    <origin rpy="0 0 0" xyz="0.738 -0.255 0.355"/>
    <parent link="base_link"/>
    <child link="Revolute2_1"/>
    <axis xyz="0.0 -0.0 1.0"/>
    <limit effort="10000" velocity="30.0"/>
  </joint>
  <joint name="Revolute3_to_base_link" type="continuous">
    <origin rpy="0 0 0" xyz="-0.738 0.255 0.355"/>
    <parent link="base_link"/>
    <child link="Revolute3_1"/>
    <axis xyz="0.0 -0.0 1.0"/>
    <limit effort="10000" velocity="30.0"/>
  </joint>
  <joint name="Revolute4_to_base_link" type="continuous">
    <origin rpy="0 0 0" xyz="-0.738 -0.255 0.355"/>
    <parent link="base_link"/>
    <child link="Revolute4_1"/>
    <axis xyz="0.0 -0.0 1.0"/>
    <limit effort="10000" velocity="30.0"/>
  </joint>
  <joint name="Wheel1_to_Revolute1" type="continuous">
    <origin rpy="0 0 0" xyz="0.0 0.0 -0.23"/>
    <parent link="Revolute1_1"/>
    <child link="Wheel1_1"/>
    <axis xyz="0.0 1.0 0.0"/>
    <limit effort="10000" velocity="30.0"/>
  </joint>
  <joint name="Wheel2_to_Revolute2" type="continuous">
    <origin rpy="0 0 0" xyz="0.0 0.0 -0.23"/>
    <parent link="Revolute2_1"/>
    <child link="Wheel2_1"/>
    <axis xyz="0.0 1.0 0.0"/>
    <limit effort="10000" velocity="30.0"/>
  </joint>
  <joint name="Wheel3_to_Revolute3" type="continuous">
    <origin rpy="0 0 0" xyz="0.0 0.0 -0.23"/>
    <parent link="Revolute3_1"/>
    <child link="Wheel3_1"/>
    <axis xyz="0.0 1.0 0.0"/>
    <limit effort="10000" velocity="30.0"/>
  </joint>
  <joint name="Wheel4_to_Revolute4" type="continuous">
    <origin rpy="0 0 0" xyz="0.0 0.0 -0.23"/>
    <parent link="Revolute4_1"/>
    <child link="Wheel4_1"/>
    <axis xyz="0.0 1.0 0.0"/>
    <limit effort="10000" velocity="30.0"/>
  </joint>
  <!-- Specify some standard inertial calculations https://en.wikipedia.org/wiki/List_of_moments_of_inertia -->
  <!-- These make use of xacro's mathematical functionality -->
  <!--
    Base UR robot series xacro macro.

    NOTE this is NOT a URDF. It cannot directly be loaded by consumers
    expecting a flattened '.urdf' file. See the top-level '.xacro' for that
    (but note that .xacro must still be processed by the xacro command).

    This file models the base kinematic chain of a UR robot, which then gets
    parameterised by various configuration files to convert it into a UR3(e),
    UR5(e), UR10(e) or UR16e, etc.

    NOTE the default kinematic parameters (i.e., link lengths, frame locations,
    offsets, etc) do not correspond to any particular robot. They are defaults
    only. There WILL be non-zero offsets between the Forward Kinematics results
    in TF (i.e., robot_state_publisher) and the values reported by the Teach
    Pendant.

    For accurate (and robot-specific) transforms, the 'kinematics_parameters_file'
    parameter MUST point to a .yaml file containing the appropriate values for
    the targeted robot.

    If using the UniversalRobots/Universal_Robots_ROS_Driver, follow the steps
    described in the readme of that repository to extract the kinematic
    calibration from the controller and generate the required .yaml file.

    Main author of the migration to yaml configs Ludovic Delval.

    Contributors to previous versions (in no particular order)

     - Denis Stogl
     - Lovro Ivanov
     - Felix Messmer
     - Kelsey Hawkins
     - Wim Meeussen
     - Shaun Edwards
     - Nadia Hammoudeh Garcia
     - Dave Hershberger
     - G. vd. Hoorn
     - Philip Long
     - Dave Coleman
     - Miguel Prada
     - Mathias Luedtke
     - Marcel Schnirring
     - Felix von Drigalski
     - Felix Exner
     - Jimmy Da Silva
     - Ajit Krisshna N L
     - Muhammad Asif Rana
  -->
  <!--
    NOTE the macro defined in this file is NOT part of the public API of this
          package. Users CANNOT rely on this file being available, or stored in
          this location. Nor can they rely on the existence of the macro.
  -->
  <ros2_control name="ur10" type="system">
    <hardware>
      <plugin>gazebo_ros2_control/GazeboSystem</plugin>
    </hardware>
    <joint name="ur10_shoulder_pan_joint">
      <command_interface name="position"/>
      <command_interface name="velocity"/>
      <command_interface name="effort"/>
      <state_interface name="position">
        <!-- initial position for the FakeSystem and simulation -->
        <param name="initial_value">0.0</param>
      </state_interface>
      <state_interface name="velocity"/>
      <state_interface name="effort"/>
    </joint>
    <joint name="ur10_shoulder_lift_joint">
      <command_interface name="position"/>
      <command_interface name="velocity"/>
      <command_interface name="effort"/>
      <state_interface name="position">
        <!-- initial position for the FakeSystem and simulation -->
        <param name="initial_value">-1.57</param>
      </state_interface>
      <state_interface name="velocity"/>
      <state_interface name="effort"/>
    </joint>
    <joint name="ur10_elbow_joint">
      <command_interface name="position"/>
      <command_interface name="velocity"/>
      <command_interface name="effort"/>
      <state_interface name="position">
        <!-- initial position for the FakeSystem and simulation -->
        <param name="initial_value">0.0</param>
      </state_interface>
      <state_interface name="velocity"/>
      <state_interface name="effort"/>
    </joint>
    <joint name="ur10_wrist_1_joint">
      <command_interface name="position"/>
      <command_interface name="velocity"/>
      <command_interface name="effort"/>
      <state_interface name="position">
        <!-- initial position for the FakeSystem and simulation -->
        <param name="initial_value">-1.57</param>
      </state_interface>
      <state_interface name="velocity"/>
      <state_interface name="effort"/>
    </joint>
    <joint name="ur10_wrist_2_joint">
      <command_interface name="position"/>
      <command_interface name="velocity"/>
      <command_interface name="effort"/>
      <state_interface name="position">
        <!-- initial position for the FakeSystem and simulation -->
        <param name="initial_value">0.0</param>
      </state_interface>
      <state_interface name="velocity"/>
      <state_interface name="effort"/>
    </joint>
    <joint name="ur10_wrist_3_joint">
      <command_interface name="position"/>
      <command_interface name="velocity"/>
      <command_interface name="effort"/>
      <state_interface name="position">
        <!-- initial position for the FakeSystem and simulation -->
        <param name="initial_value">0.0</param>
      </state_interface>
      <state_interface name="velocity"/>
      <state_interface name="effort"/>
    </joint>
  </ros2_control>
  <!-- Add URDF transmission elements (for ros_control) -->
  <!--<xacro:ur_arm_transmission prefix="${prefix}" hw_interface="${transmission_hw_interface}" />-->
  <!-- Placeholder for ros2_control transmission which don't yet exist -->
  <!-- links -  main serial chain -->
  <link name="ur10_base_link"/>
  <link name="ur10_base_link_inertia">
    <visual>
      <origin rpy="0 0 3.141592653589793" xyz="0 0 0"/>
      <geometry>
        <mesh filename="file:///home/loc/new_design_ws/install/ur_description/share/ur_description/meshes/ur10/visual/base.dae"/>
      </geometry>
    </visual>
    <collision>
      <origin rpy="0 0 3.141592653589793" xyz="0 0 0"/>
      <geometry>
        <mesh filename="file:///home/loc/new_design_ws/install/ur_description/share/ur_description/meshes/ur10/collision/base.stl"/>
      </geometry>
    </collision>
    <inertial>
      <mass value="4.0"/>
      <origin rpy="0 0 0" xyz="0 0 0"/>
      <inertia ixx="0.0061063308908" ixy="0.0" ixz="0.0" iyy="0.0061063308908" iyz="0.0" izz="0.01125"/>
    </inertial>
  </link>
  <link name="ur10_shoulder_link">
    <visual>
      <origin rpy="0 0 3.141592653589793" xyz="0 0 0"/>
      <geometry>
        <mesh filename="file:///home/loc/new_design_ws/install/ur_description/share/ur_description/meshes/ur10/visual/shoulder.dae"/>
      </geometry>
    </visual>
    <collision>
      <origin rpy="0 0 3.141592653589793" xyz="0 0 0"/>
      <geometry>
        <mesh filename="file:///home/loc/new_design_ws/install/ur_description/share/ur_description/meshes/ur10/collision/shoulder.stl"/>
      </geometry>
    </collision>
    <inertial>
      <mass value="7.1"/>
      <origin rpy="1.570796326794897 0 0" xyz="0.021 -0.027 0.0"/>
      <inertia ixx="0.03408" ixy="2e-05" ixz="-0.00425" iyy="0.03529" iyz="8e-05" izz="0.02156"/>
    </inertial>
  </link>
  <link name="ur10_upper_arm_link">
    <visual>
      <origin rpy="1.5707963267948966 0 -1.5707963267948966" xyz="0 0 0.220941"/>
      <geometry>
        <mesh filename="file:///home/loc/new_design_ws/install/ur_description/share/ur_description/meshes/ur10/visual/upperarm.dae"/>
      </geometry>
    </visual>
    <collision>
      <origin rpy="1.5707963267948966 0 -1.5707963267948966" xyz="0 0 0.220941"/>
      <geometry>
        <mesh filename="file:///home/loc/new_design_ws/install/ur_description/share/ur_description/meshes/ur10/collision/upperarm.stl"/>
      </geometry>
    </collision>
    <inertial>
      <mass value="12.7"/>
      <origin rpy="0 0 0" xyz="-0.232 0.0 0.158"/>
      <inertia ixx="0.02814" ixy="5e-05" ixz="-0.01561" iyy="0.77068" iyz="2e-05" izz="0.76943"/>
    </inertial>
  </link>
  <link name="ur10_forearm_link">
    <visual>
      <origin rpy="1.5707963267948966 0 -1.5707963267948966" xyz="0 0 0.049042"/>
      <geometry>
        <mesh filename="file:///home/loc/new_design_ws/install/ur_description/share/ur_description/meshes/ur10/visual/forearm.dae"/>
      </geometry>
    </visual>
    <collision>
      <origin rpy="1.5707963267948966 0 -1.5707963267948966" xyz="0 0 0.049042"/>
      <geometry>
        <mesh filename="file:///home/loc/new_design_ws/install/ur_description/share/ur_description/meshes/ur10/collision/forearm.stl"/>
      </geometry>
    </collision>
    <inertial>
      <mass value="4.27"/>
      <origin rpy="0 0 0" xyz="-0.3323 0.0 0.068"/>
      <inertia ixx="0.01014" ixy="8e-05" ixz="0.00916" iyy="0.30928" iyz="0.0" izz="0.30646"/>
    </inertial>
  </link>
  <link name="ur10_wrist_1_link">
    <visual>
      <origin rpy="1.5707963267948966 0 0" xyz="0 0 -0.1149"/>
      <geometry>
        <mesh filename="file:///home/loc/new_design_ws/install/ur_description/share/ur_description/meshes/ur10/visual/wrist1.dae"/>
      </geometry>
    </visual>
    <collision>
      <origin rpy="1.5707963267948966 0 0" xyz="0 0 -0.1149"/>
      <geometry>
        <mesh filename="file:///home/loc/new_design_ws/install/ur_description/share/ur_description/meshes/ur10/collision/wrist1.stl"/>
      </geometry>
    </collision>
    <inertial>
      <mass value="2.0"/>
      <origin rpy="1.570796326794897 0 0" xyz="0.0 -0.018 0.007"/>
      <inertia ixx="0.00296" ixy="-1e-05" ixz="0.0" iyy="0.00222" iyz="-0.00024" izz="0.00258"/>
    </inertial>
  </link>
  <link name="ur10_wrist_2_link">
    <visual>
      <origin rpy="0 0 0" xyz="0 0 -0.1158"/>
      <geometry>
        <mesh filename="file:///home/loc/new_design_ws/install/ur_description/share/ur_description/meshes/ur10/visual/wrist2.dae"/>
      </geometry>
    </visual>
    <collision>
      <origin rpy="0 0 0" xyz="0 0 -0.1158"/>
      <geometry>
        <mesh filename="file:///home/loc/new_design_ws/install/ur_description/share/ur_description/meshes/ur10/collision/wrist2.stl"/>
      </geometry>
    </collision>
    <inertial>
      <mass value="2.0"/>
      <origin rpy="-1.570796326794897 0 0" xyz="0.0 0.018 -0.007"/>
      <inertia ixx="0.00296" ixy="-1e-05" ixz="0.0" iyy="0.00222" iyz="-0.00024" izz="0.00258"/>
    </inertial>
  </link>
  <link name="ur10_wrist_3_link">
    <visual>
      <origin rpy="1.5707963267948966 0 0" xyz="0 0 -0.0922"/>
      <geometry>
        <mesh filename="file:///home/loc/new_design_ws/install/ur_description/share/ur_description/meshes/ur10/visual/wrist3.dae"/>
      </geometry>
    </visual>
    <collision>
      <origin rpy="1.5707963267948966 0 0" xyz="0 0 -0.0922"/>
      <geometry>
        <mesh filename="file:///home/loc/new_design_ws/install/ur_description/share/ur_description/meshes/ur10/collision/wrist3.stl"/>
      </geometry>
    </collision>
    <inertial>
      <mass value="0.365"/>
      <origin rpy="0 0 0" xyz="0.0 0 -0.026"/>
      <inertia ixx="0.0004" ixy="0.0" ixz="0.0" iyy="0.00041" iyz="0.0" izz="0.00034"/>
    </inertial>
  </link>
  <!-- base_joint fixes base_link to the environment -->
  <joint name="ur10_base_joint" type="fixed">
    <origin rpy="0 0 3.141592653589793" xyz="0.5 0 1.0"/>
    <parent link="base_link"/>
    <child link="ur10_base_link"/>
  </joint>
  <!-- joints - main serial chain -->
  <joint name="ur10_base_link-base_link_inertia" type="fixed">
    <parent link="ur10_base_link"/>
    <child link="ur10_base_link_inertia"/>
    <!-- 'base_link' is REP-103 aligned (so X+ forward), while the internal
           frames of the robot/controller have X+ pointing backwards.
           Use the joint between 'base_link' and 'base_link_inertia' (a dummy
           link/frame) to introduce the necessary rotation over Z (of pi rad).
      -->
    <origin rpy="0 0 3.141592653589793" xyz="0 0 0"/>
  </joint>
  <joint name="ur10_shoulder_pan_joint" type="revolute">
    <parent link="ur10_base_link_inertia"/>
    <child link="ur10_shoulder_link"/>
    <origin rpy="0 0 0" xyz="0 0 0.1273"/>
    <axis xyz="0 0 1"/>
    <limit effort="500" lower="-6.283185307179586" upper="6.283185307179586" velocity="2.0943951023931953"/>
    <dynamics damping="0" friction="0"/>
  </joint>
  <joint name="ur10_shoulder_lift_joint" type="revolute">
    <parent link="ur10_shoulder_link"/>
    <child link="ur10_upper_arm_link"/>
    <origin rpy="1.570796327 0 0" xyz="0 0 0"/>
    <axis xyz="0 0 1"/>
    <limit effort="500" lower="-6.283185307179586" upper="3.141592653589793" velocity="2.0943951023931953"/>
    <dynamics damping="0" friction="0"/>
  </joint>
  <joint name="ur10_elbow_joint" type="revolute">
    <parent link="ur10_upper_arm_link"/>
    <child link="ur10_forearm_link"/>
    <origin rpy="0 0 0" xyz="-0.612 0 0"/>
    <axis xyz="0 0 1"/>
    <limit effort="300" lower="-4.71238898038469" upper="3.141592653589793" velocity="3.141592653589793"/>
    <dynamics damping="0" friction="0"/>
  </joint>
  <joint name="ur10_wrist_1_joint" type="revolute">
    <parent link="ur10_forearm_link"/>
    <child link="ur10_wrist_1_link"/>
    <origin rpy="0 0 0" xyz="-0.5723 0 0.163941"/>
    <axis xyz="0 0 1"/>
    <limit effort="100" lower="-3.141592653589793" upper="3.141592653589793" velocity="3.141592653589793"/>
    <dynamics damping="0" friction="0"/>
  </joint>
  <joint name="ur10_wrist_2_joint" type="revolute">
    <parent link="ur10_wrist_1_link"/>
    <child link="ur10_wrist_2_link"/>
    <origin rpy="1.570796327 0 0" xyz="0 -0.1157 -2.373046667922381e-11"/>
    <axis xyz="0 0 1"/>
    <limit effort="100" lower="-3.141592653589793" upper="3.141592653589793" velocity="3.141592653589793"/>
    <dynamics damping="0" friction="0"/>
  </joint>
  <joint name="ur10_wrist_3_joint" type="revolute">
    <parent link="ur10_wrist_2_link"/>
    <child link="ur10_wrist_3_link"/>
    <origin rpy="1.570796326589793 3.141592653589793 3.141592653589793" xyz="0 0.0922 -1.891053610911353e-11"/>
    <axis xyz="0 0 1"/>
    <limit effort="100" lower="-3.141592653589793" upper="3.141592653589793" velocity="3.141592653589793"/>
    <dynamics damping="0" friction="0"/>
  </joint>
  <link name="ur10_ft_frame"/>
  <joint name="ur10_wrist_3_link-ft_frame" type="fixed">
    <parent link="ur10_wrist_3_link"/>
    <child link="ur10_ft_frame"/>
    <origin rpy="3.141592653589793 0 0" xyz="0 0 0"/>
  </joint>
  <!-- ROS-Industrial 'base' frame - base_link to UR 'Base' Coordinates transform -->
  <link name="ur10_base"/>
  <joint name="ur10_base_link-base_fixed_joint" type="fixed">
    <!-- Note the rotation over Z of pi radians - as base_link is REP-103
           aligned (i.e., has X+ forward, Y+ left and Z+ up), this is needed
           to correctly align 'base' with the 'Base' coordinate system of
           the UR controller.
      -->
    <origin rpy="0 0 3.141592653589793" xyz="0 0 0"/>
    <parent link="ur10_base_link"/>
    <child link="ur10_base"/>
  </joint>
  <!-- ROS-Industrial 'flange' frame - attachment point for EEF models -->
  <link name="ur10_flange"/>
  <joint name="ur10_wrist_3-flange" type="fixed">
    <parent link="ur10_wrist_3_link"/>
    <child link="ur10_flange"/>
    <origin rpy="0 -1.5707963267948966 -1.5707963267948966" xyz="0 0 0"/>
  </joint>
  <!-- ROS-Industrial 'tool0' frame - all-zeros tool frame -->
  <link name="ur10_tool0"/>
  <joint name="ur10_flange-tool0" type="fixed">
    <!-- default toolframe - X+ left, Y+ up, Z+ front -->
    <origin rpy="1.5707963267948966 0 1.5707963267948966" xyz="0 0 0"/>
    <parent link="ur10_flange"/>
    <child link="ur10_tool0"/>
  </joint>
  <!-- Thêm đầu sạc  -->
  <link name="Charge_link">
    <inertial>
      <origin rpy="0 0 0" xyz="0 0 -0.0"/>
      <mass value="3.0"/>
      <inertia ixx="0.0091125" ixy="0.0" ixz="0.0" iyy="0.005781250000000001" iyz="0.0" izz="0.005781250000000001"/>
    </inertial>
    <visual>
      <geometry>
        <mesh filename="file:///home/loc/new_design_ws/install/thanxe_new_description/share/thanxe_new_description/meshes/dausac.stl" scale="0.001 0.001 0.001"/>
      </geometry>
      <material name="gold"/>
    </visual>
    <collision>
      <geometry>
        <mesh filename="file:///home/loc/new_design_ws/install/thanxe_new_description/share/thanxe_new_description/meshes/dausac.stl" scale="0.00099 0.00099 0.00099"/>
      </geometry>
    </collision>
  </link>
  <joint name="Charge_link_to_ur10_tool0" type="fixed">
    <origin rpy="0 3.141592653589793 -3.141592653589793" xyz="0 0.0 0"/>
    <parent link="ur10_tool0"/>
    <child link="Charge_link"/>
  </joint>
  <link name="charging_tcp"/>
  <joint name="charge_to_tcp" type="fixed">
    <parent link="Charge_link"/>
    <child link="charging_tcp"/>
    <origin rpy="0 0 0" xyz="0.0 0.2022 -0.0812"/>
  </joint>
  <link name="base_camera_link">
    <inertial>
      <mass value="0.05"/>
      <origin rpy="0 0 0" xyz="0 0 0"/>
      <inertia ixx="0.0001" ixy="0" ixz="0" iyy="0.0001" iyz="0" izz="0.0001"/>
    </inertial>
    <visual>
      <geometry>
        <box size="0.01 0.03 0.03"/>
      </geometry>
      <material name="Red">
        <color rgba="1 0 0 1"/>
      </material>
    </visual>
    <collision>
      <geometry>
        <box size="0.01 0.03 0.03"/>
      </geometry>
    </collision>
  </link>
  <joint name="base_camera_joint" type="fixed">
    <parent link="base_link"/>
    <child link="base_camera_link"/>
    <origin rpy="0 0.15 0" xyz="0.88 0 0.85"/>
  </joint>
  <link name="base_camera_link_optical"/>
  <joint name="base_camera_optical_joint" type="fixed">
    <parent link="base_camera_link"/>
    <child link="base_camera_link_optical"/>
    <origin rpy="-1.5707963267948966 0 -1.5707963267948966" xyz="0 0 0"/>
  </joint>
  <gazebo reference="base_camera_link">
    <material>Gazebo/Red</material>
    <sensor name="base_camera_sensor" type="depth">
      <update_rate>10.0</update_rate>
      <visualize>true</visualize>
      <always_on>true</always_on>
      <camera name="base_camera">
        <horizontal_fov>0.8</horizontal_fov>
        <image>
          <width>1280</width>
          <height>720</height>
          <format>R8G8B8</format>
        </image>
        <clip>
          <near>0.01</near>
          <far>40</far>
        </clip>
      </camera>
      <plugin filename="libgazebo_ros_camera.so" name="base_camera_controller">
        <ros>
          <namespace>base_camera</namespace>
          <remapping>image_raw:=image_raw</remapping>
          <remapping>camera_info:=camera_info</remapping>
          <remapping>depth/image_raw:=depth/image_raw</remapping>
          <remapping>depth/camera_info:=depth/camera_info</remapping>
          <remapping>points:=points</remapping>
        </ros>
        <frame_name>base_camera_link_optical</frame_name>
        <hack_baseline>0.07</hack_baseline>
        <min_depth>0.01</min_depth>
        <max_depth>40</max_depth>
      </plugin>
    </sensor>
  </gazebo>
  <link name="arm_camera_link">
    <inertial>
      <mass value="0.05"/>
      <origin rpy="0 0 0" xyz="0 0 0"/>
      <inertia ixx="0.0001" ixy="0" ixz="0" iyy="0.0001" iyz="0" izz="0.0001"/>
    </inertial>
    <visual>
      <geometry>
        <box size="0.01 0.03 0.03"/>
      </geometry>
      <material name="Red">
        <color rgba="1 0 0 1"/>
      </material>
    </visual>
    <collision>
      <geometry>
        <box size="0.01 0.03 0.03"/>
      </geometry>
    </collision>
  </link>
  <joint name="arm_camera_joint" type="fixed">
    <parent link="Charge_link"/>
    <child link="arm_camera_link"/>
    <origin rpy="0 0.17453292519943295 1.5707963267948966" xyz="0 0.07 0.05"/>
  </joint>
  <link name="arm_camera_link_optical"/>
  <joint name="arm_camera_optical_joint" type="fixed">
    <parent link="arm_camera_link"/>
    <child link="arm_camera_link_optical"/>
    <origin rpy="-1.5707963267948966 0 -1.5707963267948966" xyz="0 0 0"/>
  </joint>
  <gazebo reference="arm_camera_link">
    <material>Gazebo/Red</material>
    <sensor name="arm_camera_sensor" type="depth">
      <update_rate>10.0</update_rate>
      <visualize>true</visualize>
      <always_on>true</always_on>
      <camera name="arm_camera">
        <horizontal_fov>0.8</horizontal_fov>
        <image>
          <width>1280</width>
          <height>720</height>
          <format>R8G8B8</format>
        </image>
        <clip>
          <near>0.02</near>
          <far>50</far>
        </clip>
      </camera>
      <plugin filename="libgazebo_ros_camera.so" name="arm_camera_controller">
        <ros>
          <namespace>arm_camera</namespace>
          <remapping>image_raw:=image_raw</remapping>
          <remapping>camera_info:=camera_info</remapping>
          <remapping>depth/image_raw:=depth/image_raw</remapping>
          <remapping>depth/camera_info:=depth/camera_info</remapping>
          <remapping>points:=points</remapping>
        </ros>
        <frame_name>arm_camera_link_optical</frame_name>
        <hack_baseline>0.07</hack_baseline>
        <min_depth>0.02</min_depth>
        <max_depth>50</max_depth>
      </plugin>
    </sensor>
  </gazebo>
  <gazebo>
    <plugin filename="libgazebo_ros2_control.so" name="gazebo_ros2_control">
      <parameters>/home/loc/new_design_ws/install/thanxe_new_description/share/thanxe_new_description/config/combine_controller.yaml</parameters>
    </plugin>
  </gazebo>
  <!-- LIDAR -->
  <link name="laser_frame">
    <visual>
      <geometry>
        <cylinder length="0.04" radius="0.05"/>
      </geometry>
      <material name="red"/>
    </visual>
    <collision>
      <geometry>
        <cylinder length="0.04" radius="0.05"/>
      </geometry>
    </collision>
    <inertial>
      <origin rpy="0 0 0" xyz="0 0 0"/>
      <mass value="0.1"/>
      <inertia ixx="7.583333333333335e-05" ixy="0.0" ixz="0.0" iyy="7.583333333333335e-05" iyz="0.0" izz="0.00012500000000000003"/>
    </inertial>
  </link>
  <joint name="laser_joint" type="fixed">
    <parent link="base_link"/>
    <child link="laser_frame"/>
    <origin rpy="0 0 0" xyz="0.95 0 0.55"/>
  </joint>
  <gazebo reference="laser_frame">
    <material>Gazebo/Red</material>
    <pose> 0 0 0 0 0 0 </pose>
    <sensor name="laser" type="ray">
      <update_rate>15</update_rate>
      <visualize>false</visualize>
      <ray>
        <scan>
          <horizontal>
            <samples>360</samples>
            <min_angle>-1.57</min_angle>
            <max_angle>1.57</max_angle>
          </horizontal>
        </scan>
        <range>
          <min>0.1</min>
          <max>40</max>
        </range>
      </ray>
      <plugin filename="libgazebo_ros_ray_sensor.so" name="laser_controller">
        <ros>
          <argument>~/out:=scan</argument>
        </ros>
        <output_type>sensor_msgs/LaserScan</output_type>
        <frame_name>laser_frame</frame_name>
      </plugin>
    </sensor>
  </gazebo>
</robot>
